Workbook

Sheet Reports

Sheet Overall Summary
A1: Workstream Overview: | O1: Date :25/03/2026
B3: CAB | D3: Yet to Create
B4: Sprint | D4: 3 | L4: QA Exexution Progress | P4: =SUM(N6:Q6)/M6 -> 1
B5: Sprint Cycle | D5: 2nd Mar - 13th Mar | L5: Story | M5: TS Coverage | N5: Pass | O5: Fail | P5: Blocked | Q5: Deferred | R5: Pending
B6: Say/Do Ratio | D6: =SUM(P24)/N26 -> 1 | L6: ='TestCase Coverage'!A12 -> 6 | M6: ='TestCase Coverage'!B12 -> 49 | N6: ='TestCase Coverage'!C12 -> 49 | O6: ='TestCase Coverage'!D12 -> 0 | P6: ='TestCase Coverage'!E12 -> 0 | Q6: ='TestCase Coverage'!F12 -> 0 | R6: ='TestCase Coverage'!G12 -> 0
B7: Overall Status | D7: Green
B9: Progress Summary this Cycle
B10: - Worked on fixing existing master script failures - 6 New test case added for Renewall and Amendment and OnDemand order creation. - Scripting Completed for Renewal, amendment & OnDemand order scenarios, Paymonthly project changes, Adhoc order creation scenarios from Roadmap/Project team, - Updated scripts based on the new Order page UI changes and bulk data Order creation, fulfillment and shipments details process. - 6 application defects logged through automation ( QETA-27727 , QETA-27735, QETA-27807, QETA-27904, QETA-27807, QETA-27897 )
B15: Issues & Risks
B16: -
B21: Defects Trend | D21: P0 | E21: P1 | F21: P2 | G21: P3 | H21: P4 | L21: Progress This Cycle | N21: stories ready for QA | O21: stories QA In-Progress | P21: stories QA Completed | Q21: stories ready for UAT | R21: UAT Completed
B22: Open | D22: =#REF! -> #REF! | E22: =#REF! -> #REF! | F22: =#REF! -> #REF! | G22: =#REF! -> #REF! | H22: 0 | I22: =SUM(D22:H22) -> #REF! | L22: Stories | N22: 0 | O22: 0 | P22: 6 | Q22: 5 | R22: 1
B23: Closed | D23: =Sheet1!C23 -> 2 | E23: =Sheet1!C24 -> 2 | F23: =Sheet1!C25 -> 3 | G23: =Sheet1!C26 | H23: 0 | I23: =SUM(D23:H23) -> 7 | L23: Tasks | N23: 0 | O23: 0 | P23: 0 | Q23: 0 | R23: 0
B24: Reopen | D24: 0 | E24: 0 | F24: 0 | G24: 0 | H24: 0 | I24: =SUM(D24:H24) -> 0 | N24: =SUM(N22:N23) -> 0 | O24: =SUM(O22:O23) -> 0 | P24: =SUM(P22:P23) -> 6 | Q24: =SUM(Q22:Q23) -> 5 | R24: =SUM(R22:R23) -> 1
I25: =SUM(I22:I24) -> #REF! | L25: Total Stories Planned | N25: 6
L26: QA Qualified | N26: 6
L27: Spill-Overs | N27: 0
B29: Automation Coverage | I29: =F31/B31 -> #DIV/0!
B30: Automation Candidates | D30: Cannot Be Automated | F30: Automated Tests | H30: Pending TCs for Automation | J30: Partially Automated - Feature not developed
B31: 0 | D31: ='TestCase Coverage'!J12 -> 13 | F31: ='TestCase Coverage'!K12 -> 0 | H31: ='TestCase Coverage'!L12 -> 14 | J31: ='TestCase Coverage'!M12 -> 22

Sheet TestCase Coverage
A2: Coverage | B2: =SUM(C12:F12)/B12 -> 1 | M2: =K12/I12 -> #DIV/0!
A3: Story | B3: TS Coverage | C3: Pass | D3: Fail | E3: Blocked | F3: Deferred | G3: In Progress | H3: Pending | I3: Automation Candidates | J3: Cannot Be Automated | K3: Automated Tests | L3: Pending TCs for Automation | M3: Partially Automated - Feature not developed
A4: PRDOPS-490 | B4: 6 | C4: 6 | D4: 0 | E4: 0 | F4: 0 | G4: 0 | H4: 0 | I4: 0 | J4: 6 | K4: 0 | L4: 0 | M4: 0
A5: PRDOPS-415 | B5: 7 | C5: 7 | D5: 0 | E5: 0 | F5: 0 | G5: 0 | H5: 0 | I5: 0 | J5: 7 | K5: 0 | L5: 0 | M5: 0
A6: PRDOPS-413 | B6: 8 | C6: 8 | D6: 0 | E6: 0 | F6: 0 | G6: 0 | H6: 0 | I6: 0 | J6: 0 | K6: 0 | L6: 0 | M6: 8
A7: PRDOPS-477 | B7: 14 | C7: 14 | D7: 0 | E7: 0 | F7: 0 | G7: 0 | H7: 0 | I7: 0 | J7: 0 | K7: 0 | L7: 0 | M7: 14
A8: PRDOPS-470 | B8: 10 | C8: 10 | D8: 0 | E8: 0 | F8: 0 | G8: 0 | H8: 0 | I8: 0 | J8: 0 | K8: 0 | L8: 10 | M8: 0
A9: PRDOPS-23 | B9: 4 | C9: 4 | D9: 0 | E9: 0 | F9: 0 | G9: 0 | H9: 0 | I9: 0 | J9: 0 | K9: 0 | L9: 4 | M9: 0
A12: =COUNTA(A4:A11) -> 6 | B12: =SUM(B4:B11) -> 49 | C12: =SUM(C4:C11) -> 49 | D12: =SUM(D4:D11) -> 0 | E12: =SUM(E4:E11) -> 0 | F12: =SUM(F4:F11) -> 0 | G12: =SUM(G4:G11) -> 0 | H12: =SUM(H4:H11) -> 0 | I12: =SUM(I4:I11) -> 0 | ... M12: =SUM(M4:M11) -> 22
A14: Story | B14: Module | C14: Test Case ID | D14: Test Case | E14: Test Case Description | F14: Expected Result | G14: Status | H14: Tested by | I14: Identified for Automation | J14: Automated
A15: PRDOPS-490 | B15: NS | C15: PRDOPS-490-TC-001 | D15: Verify that NS-SFDC Sync Status is updated to "Failed" in the NetSuite Fulfillment Status Record. | E15: Verify Integration Response Record Creation in NetSuite | F15: 1.NS-SFDC Sync Status = "Failed" 2.Failure reason is logged correctly. 3.No incorrect status like Success/Completed. | G15: Pass | H15: Madhu Peketi | I15: No | J15: Cannot Automate
B16: NS | C16: PRDOPS-490-TC-002 | D16: Verify NetSuite sends failure notification email twice daily. - Schedule: Daily 11.45 PM PST and 11.45 AM PST | E16: Email Trigger – Twice Daily | F16: 1.Email sent twice daily. 2.Trigger occurs only if failed records exist. 3.No duplicate emails within same schedule cycle. | G16: Pass | H16: Madhu Peketi | I16: No | J16: Cannot Automate
B17: NS | C17: PRDOPS-490-TC-003 | D17: Validate Subject, Recipient and Body of email. | E17: Email Content Validation | F17: Subject must be exactly: Report: Order failed to shipped in SFDC To: prodopsapps@rubrik.com Email Body must contain: Hi Team, Please find attached the list of order failed to get shipped in SFDC. Review and try to fix this asap. Thanks! | G17: Pass | H17: Madhu Peketi | I17: No | J17: Cannot Automate
B18: NS | C18: PRDOPS-490-TC-004 | D18: Verify CSV file attachment and its contents. | E18: CSV Attachment Validation | F18: 1.CSV file attached. 2.File opens without corruption. 3.Contains correct columns (Example): Order Number Fulfillment ID Failure Reason Sync Status Timestamp 4.Data matches NetSuite failed records. | G18: Pass | H18: Madhu Peketi | I18: No | J18: Cannot Automate
B19: NS | C19: PRDOPS-490-TC-005 | D19: Verify all failed records are included in one CSV file. | E19: Multiple Failed Records in Same Email | F19: 1.All failed records are listed. 2.No missing entries. 3.No duplicate entries. | G19: Pass | H19: Madhu Peketi | I19: No | J19: Cannot Automate
B20: NS | C20: PRDOPS-490-TC-006 | D20: Verify behavior when no failed sync records exist. | E20: Negative Scenario – No Failed Records | F20: No email sent (OR) Email sent indicating "No failed records" (as per business rule). | G20: Pass | H20: Madhu Peketi | I20: No | J20: Cannot Automate
A22: PRDOPS-415 | B22: SFDC/NS | C22: PRDOPS-415-TC-001 | D22: Verify that a new integration response record is created in NetSuite when SFDC Order does not capture NetSuite ID during booking. | E22: Verify Integration Response Record Creation in NetSuite | F22: 1.A new Integration Response Record is created in NetSuite. 2.Record contains error details indicating missing NetSuite ID in SFDC. 3.Timestamp and Order reference are correct. 4. Error Msg : Error Message: Could not find NetSuite_Order__c in SFDC ORDER. | G22: Pass | H22: Madhu Peketi | I22: No | J22: Cannot Automate
B23: SFDC/NS | C23: PRDOPS-415-TC-002 | D23: Verify that a new integration response record is created in NetSuite when SFDC Order does not capture NetSuite ID during booking. | E23: Verify Integration Response Record Creation in NetSuite | F23: 1.A new Integration Response Record is created in NetSuite. 2.Record contains error details indicating missing NetSuite ID in SFDC. 3.Timestamp and Order reference are correct. 4. Error Msg : Error Message: Could not find NetSuite_Order__c in SFDC ORDER | G23: Pass | H23: Madhu Peketi | I23: No | J23: Cannot Automate
B24: SFDC/NS | C24: PRDOPS-415-TC-003 | D24: Verify that Sync Status is updated to "Failed" in NetSuite Fulfillment Status Record.- Test Order EDI | E24: Verify NS-SFDC Sync Status Updated to "Failed" | F24: 1.NS-SFDC Sync Status = "Failed" 2.Failure reason logged properly. 3.No duplicate status updates. 4. Error Msg : Error Message: Could not find NetSuite_Order__c in SFDC ORDER | G24: Pass | H24: Madhu Peketi | I24: No | J24: Cannot Automate
B25: SFDC/NS | C25: PRDOPS-415-TC-004 | D25: Verify that Sync Status is updated to "Failed" in NetSuite Fulfillment Status Record.- Test Order Non-EDI - (Use Product :: SELECT Id, Name FROM Product2 WHERE Order_Fulfillment__c = 'Manual') | E25: Verify NS-SFDC Sync Status Updated to "Failed" | F25: 1.NS-SFDC Sync Status = "Failed" 2.Failure reason logged properly. 3.No duplicate status updates. 4. Error Msg : Error Message: Could not find NetSuite_Order__c in SFDC ORDER | G25: Pass | H25: Madhu Peketi | I25: No | J25: Cannot Automate
B26: SFDC/NS | C26: PRDOPS-415-TC-005 | D26: Verify that Sync Status is updated to "Failed" in NetSuite Fulfillment Status Record.- Test Order(Manual fulfilment) | E26: Verify NS-SFDC Sync Status Updated to "Failed" | F26: 1.NS-SFDC Sync Status = "Failed" 2.Failure reason logged properly. 3.No duplicate status updates. 4. Error Msg : Error Message: Could not find NetSuite_Order__c in SFDC ORDER | G26: Pass | H26: Madhu Peketi | I26: No | J26: Cannot Automate
B27: SFDC/NS | C27: PRDOPS-415-TC-006 | D27: Verify that Sync Status is updated to "Failed" in NetSuite Fulfillment Status Record.- Test for Renewal/ Amendment Order_Auto Fulfillment | E27: Verify NS-SFDC Sync Status Updated to "Failed" | F27: 1.NS-SFDC Sync Status = "Failed" 2.Failure reason logged properly. 3.No duplicate status updates. 4. Error Msg : Error Message: Could not find NetSuite_Order__c in SFDC ORDER | G27: Pass | H27: Madhu Peketi | I27: No | J27: Cannot Automate
B28: SFDC/NS | C28: PRDOPS-415-TC-007 | D28: Verify that Sync Status is updated to "Success" in NetSuite Fulfillment Status Record. | E28: Verify NS-SFDC Sync Status Updated to "Success" | F28: 1.NS-SFDC Sync Status = "Success" 2. Error Msg should not populate | G28: Pass | H28: Madhu Peketi | I28: No | J28: Cannot Automate
A30: PRDOPS-413 | B30: SFDC | C30: PRDOPS-413-TC-001 | D30: TC_Sync_001_QE_StandardSync | E30: Verify that Opportunity and Opportunity Line updates successfully sync to Bookings, BLI, and Splits during the standard QE period. | F30: The updated values from the Opportunity and Opportunity Lines are successfully and accurately synced to the corresponding Booking, BLI, and Booking Splits. | G30: Pass | H30: Uma Mahesh | I30: Yes | J30: Partially Automated
B31: SFDC | C31: PRDOPS-413-TC-002 | D31: TC_Sync_002_QE_DebookingSync for Amount Based_Full | E31: Verify that Debooking actions trigger correct updates to Bookings during the standard QE period. | F31: The Debooking scenario is successfully processed, and the negative/adjustment values are accurately synced to the corresponding Booking, BLI, and Booking Splits. | G31: Pass | H31: Uma Mahesh | I31: Yes | J31: Partially Automated
B32: SFDC | C32: PRDOPS-413-TC-003 | D32: TC_Sync_003_QE_DebookingSync for Line Item Based_Partial | E32: Verify that Debooking actions trigger correct updates to Bookings during the standard QE period. | F32: The Debooking scenario is successfully processed, and the negative/adjustment values are accurately synced to the corresponding Booking, BLI, and Booking Splits. | G32: Pass | H32: Uma Mahesh | I32: Yes | J32: Partially Automated
B33: SFDC | C33: PRDOPS-413-TC-004 | D33: TC_Sync_004_QEPlus1_5PM_Sync | E33: Verify that Opportunity updates successfully sync on QE+1 day at 5:00 PM PST/PDT. | F33: The updates made at 5:00 PM PST/PDT are successfully synced to the corresponding Booking, BLI, and Booking Splits. | G33: Pass | H33: Uma Mahesh | I33: Yes | J33: Partially Automated
B34: SFDC | C34: PRDOPS-413-TC-005 | D34: TC_Sync_005_QEPlus1_6PM_CornerCase_Sync | E34: Verify the corner case where updates made exactly at the 6:00 PM PST/PDT cutoff on QE+1 sync within the following 15 minutes. | F34: The changes are successfully synced to the corresponding Booking, BLI, and Booking Splits within a 15-minute window after the 6:00 PM save action. | G34: Pass | H34: Uma Mahesh | I34: Yes | J34: Partially Automated
B35: SFDC | C35: PRDOPS-413-TC-006 | D35: TC_Sync_006_QEPlus1_Debooking_BeforeCutoff | E35: Verify that Debooking actions successfully sync on QE+1 day prior to the 6:00 PM PST/PDT cutoff. | F35: The Debooking action successfully syncs, and the adjustment Booking, BLI, and Splits are accurately reflected before the end of business hours. | G35: Pass | H35: Uma Mahesh | I35: Yes | J35: Partially Automated
B36: SFDC | C36: PRDOPS-413-TC-007 | D36: TC_Sync_007_QEPlus1_8PM_FrozenSync | E36: Verify that Booking sync is frozen and no updates occur for modifications made after the end of business hours (e.g., 8:00 PM PST/PDT) on QE+1. | F36: The Booking sync is completely frozen. No updates occur to the Booking, Booking Splits, or BLI. The Booking retains its previous values. | G36: Pass | H36: Uma Mahesh | I36: Yes | J36: Partially Automated
B37: SFDC | C37: PRDOPS-413-TC-008 | D37: TC_Sync_008_QEPlus1_Debooking_Frozen | E37: Verify that Debooking actions initiated after the end of business hours (e.g., 8:00 PM PST/PDT) on QE+1 do not sync to the frozen Bookings. | F37: The Booking sync is frozen. The Debooking adjustments do not sync to or alter the frozen Booking, Booking Splits, or BLI. | G37: Pass | H37: Uma Mahesh | I37: Yes | J37: Partially Automated
A39: PRDOPS-477 | B39: SFDC/NS | C39: PRDOPS-477_TC-01 | D39: Verify If the "Booked By" field is empty and the "Revised By" field is not empty,then OM users (OM Manager) except the Revised user should be able to approve the order for Non-EDI. | E39: Verify If the "Booked By" field is empty and the "Revised By" field is not empty,then OM users (OM Manager) except the Revised user should be able to approve the order for Non-EDI. | F39: When the "Booked By" field is empty and the "Revised By" field is not empty,then OM users (OM Manager) except the Revised user should be able to approve the order. | G39: Pass | H39: Sai Krishna | I39: Yes | J39: Partially Automated
B40: SFDC/NS | C40: PRDOPS-477_TC-02 | D40: Verify If the "Booked By" field is empty and the "Revised By" field is empty,then OM users (OM Manager) except the Revised user should be able to approve the order for Non-EDI. | E40: Verify If the "Booked By" field is empty and the "Revised By" field is empty,then OM users (OM Manager) except the Revised user should be able to approve the order for Non-EDI. | F40: When the "Booked By" field is empty and the "Revised By" field is empty,then OM users (OM Manager) except the Revised user should be able to approve the order for Non-EDI. | G40: Pass | H40: Sai Krishna | I40: Yes | J40: Partially Automated
B41: SFDC/NS | C41: PRDOPS-477_TC-03 | D41: Verify if the "Booked By" field is not empty and the assigned booker captured in the Booked by field then the Booker Can't be able to Approve the Order in NS for Non-EDI. | E41: Verify if the "Booked By" field is not empty and the assigned booker captured in the Booked by field then the Booker Can't be able to Approve the Order in NS for Non-EDI. | F41: When the "Booked By" field is not empty and the assigned booker captured in the Booked by field then the Booker Can't be able to Approve the Order in NS. | G41: Pass | H41: Sai Krishna | I41: Yes | J41: Partially Automated
B42: SFDC/NS | C42: PRDOPS-477_TC-04 | D42: Verify if the "Revised By" field is not empty and the assigned Reviser captured in the Revised by field then the Revised by user Can't be able to Approve the Order in NS for Non-EDI. | E42: Verify if the "Revised By" field is not empty and the assigned Reviser captured in the Revised by field then the Revised by user Can't be able to Approve the Order in NS for Non-EDI. | F42: When the "Revised By" field is not empty and the assigned Reviser captured in the Revised by field then the Revised by user Can't be able to Approve the Order in NS. | G42: Pass | H42: Sai Krishna | I42: Yes | J42: Partially Automated
B43: SFDC/NS | C43: PRDOPS-477_TC-05 | D43: Verify if the "Booked By" field is not empty and the assigned booker captured in the Booked by field then the Booker Can't be able to uncheck the approval hold check box on the order | E43: Verify if the "Booked By" field is not empty and the assigned booker captured in the Booked by field then the Booker Can't be able to uncheck the approval hold check box on the order | F43: When the "Booked By" field is not empty and the assigned booker captured in the Booked by field then the Booker Can't be able to uncheck the approval hold check box on the order | G43: Pass | H43: Sai Krishna | I43: Yes | J43: Partially Automated
B44: SFDC/NS | C44: PRDOPS-477_TC-06 | D44: Verify if the "Booked By" field is not empty & Booker is not in the "Revised by" field then Booker Can't be able to Approve the Order & Can't be able to uncheck the Approval hold checkbox on the Order. | E44: Verify if the "Booked By" field is not empty & Booker is not in the "Revised by" field then Booker Can't be able to Approve the Order & Can't be able to uncheck the Approval hold checkbox on the Order. | F44: When the "Booked By" field is not empty & Booker is not in the "Revised by" field then Booker Can't be able to Approve the Order & Can't be able to uncheck the Approval hold checkbox on the Order. | G44: Pass | H44: Sai Krishna | I44: Yes | J44: Partially Automated
B45: SFDC/NS | C45: PRDOPS-477_TC-07 | D45: Verify if the Second User updates the Order then "Submitter Email id" should be captured with the second person email id & Revised by should be captured his name. | E45: Verify if the Second User updates the Order then "Submitter Email id" should be captured with the second person email id & Revised by should be captured his name. | F45: When the Second person updates the Order then his name will capture in the Revised by. Now "Booker by" & "Revised by" both can't be able to approve the Order and Approval Hold button. | G45: Pass | H45: Sai Krishna | I45: Yes | J45: Partially Automated
B46: SFDC/NS | C46: PRDOPS-477_TC-08 | D46: Verify if the Third User updates the Order then "Submitter Email id" should be captured with the second & Third person email id's & All Revised by should be captured his name. | E46: Verify if the Third User updates the Order then "Submitter Email id" should be captured with the second & Third person email id's & All Revised by should be captured his name. | F46: When the Third person updates the Order then his name will capture in the Revised by. Now "Booker by" & All "Revised by" can't be able to approve the Order and Approval Hold button. | G46: Pass | H46: Sai Krishna | I46: Yes | J46: Partially Automated
B47: SFDC/NS | C47: PRDOPS-477_TC-09 | D47: Verify the Sync Timing issue by Updating the Same Order at the Sametime with different users. The Changes should sync from SFDC to NS. | E47: Verify the Sync Timing issue by Updating the Same Order at the Sametime with different users. The Changes should sync from SFDC to NS. | F47: When the User Sync the Same Order at the Sametime with different users then the Changes should sync from SFDC to NS. | G47: Pass | H47: Sai Krishna | I47: Yes | J47: Partially Automated
...

Sheet Sheet1
A4: QA Summary of Story Cards:
A5: Track | B5: QA Qualified | C5: QA Completed | D5: Ready for UAT | E5: UAT Completed | F5: Savings due to Test Automaton in hrs / Sprint
A6: PRDOPS | B6: 6 | C6: 6 | D6: 5 | E6: 1 | F6: 14 hr
A10: QA Summary of Test Cases:
A11: Sl No | B11: Story Cards | C11: Total no. of Test Cases | D11: Pass | E11: Execution % | F11: Defects | G11: Defect Density (%) | H11: Defect Leakage (%) | I11: Defect Rejection Rate (%) | J11: QA Automation Savings in (hrs) | K11: Comments | N11: Defects | O11: P0 | P11: P1 | Q11: P2 | R11: P3 | S11: No Action
A12: 1 | B12: ='TestCase Coverage'!A4 -> PRDOPS-490 | C12: ='TestCase Coverage'!B4 -> 6 | D12: ='TestCase Coverage'!C4 -> 6 | E12: 1 | F12: =N12 -> 1 | G12: =N12/C12*100 -> 16.666667 | H12: 0 | I12: 0 | J12: 2 | K12: We have used our test automation for test data creation. | N12: =SUM(O12:R12) -> 1 | O12: 0 | P12: 0 | Q12: 1 | R12: 0 | S12: 0
A13: 2 | B13: ='TestCase Coverage'!A5 -> PRDOPS-415 | C13: ='TestCase Coverage'!B5 -> 7 | D13: ='TestCase Coverage'!C5 -> 7 | E13: 1 | F13: =N13 -> 1 | G13: =N13/C13*100 -> 14.285714 | H13: 0 | I13: 0 | J13: 2 | N13: =SUM(O13:R13) -> 1 | O13: 0 | P13: 0 | Q13: 1 | R13: 0 | S13: 0
A14: 3 | B14: ='TestCase Coverage'!A7 -> PRDOPS-477 | C14: ='TestCase Coverage'!B7 -> 14 | D14: ='TestCase Coverage'!C7 -> 14 | E14: 1 | F14: =N14 -> 3 | G14: =N14/C14*100 -> 21.428571 | H14: 0 | I14: 0 | J14: 2 | N14: =SUM(O14:R14) -> 3 | O14: 1 | P14: 2 | Q14: 0 | R14: 0
A15: 4 | B15: ='TestCase Coverage'!A8 -> PRDOPS-470 | C15: ='TestCase Coverage'!B8 -> 10 | D15: ='TestCase Coverage'!C8 -> 10 | E15: 1 | F15: =N15 -> 1 | G15: =N15/C15*100 -> 10 | H15: 0 | I15: 0 | J15: 4 | N15: =SUM(O15:R15) -> 1 | O15: 0 | P15: 0 | Q15: 1 | R15: 0 | S15: 1
A16: 5 | B16: ='TestCase Coverage'!A6 -> PRDOPS-413 | C16: ='TestCase Coverage'!B6 -> 8 | D16: ='TestCase Coverage'!C6 -> 8 | E16: 1 | F16: =N16 -> 0 | G16: =N16/C16*100 -> 0 | H16: 0 | I16: 0 | J16: 4 | N16: =SUM(O16:R16) -> 0 | O16: 0 | P16: 0 | Q16: 0 | R16: 0 | S16: 0
A17: 6 | B17: ='TestCase Coverage'!A9 -> PRDOPS-23 | C17: ='TestCase Coverage'!B9 -> 4 | D17: ='TestCase Coverage'!C9 -> 4 | E17: 1 | F17: =N17 -> 1 | G17: =N17/C17*100 -> 25 | H17: 0 | I17: 0 | J17: 0 | K17: Scripting is in progress for On Demand orders. | N17: =SUM(O17:R17) -> 1 | O17: 1 | P17: 0 | Q17: 0 | R17: 0 | S17: 2
A18: =COUNT(A12:A17) -> 6 | B18: =COUNT(B12:B17) -> 0 | C18: =SUM(C12:C17) -> 49 | D18: =SUM(D12:D17) -> 49 | E18: =AVERAGE(E12:E17) -> 1 | F18: =N18 -> 7 | G18: =AVERAGE(G12:G17) -> 14.563492 | H18: =SUM(H12:H17) -> 0 | I18: =SUM(I12:I17) -> 0 | J18: =SUM(J12:J17) -> 14 | M18: Total | N18: =SUM(O18:R18) -> 7 | O18: =SUM(O12:O17) -> 2 | P18: =SUM(P12:P17) -> 2 | Q18: =SUM(Q12:Q17) -> 3 | R18: =SUM(R12:R17) -> 0 | S18: =SUM(S12:S17) -> 3
M19: Other Issues/No Action | N19: =S18 -> 3
A20: Bug Report : | M20: Total Issue | N20: =SUM(N18:N19) -> 10
A21: While testing the above test execution we have come across the following defects in QA Sandbox.
A22: Total Number of Defects | C22: Close | D22: Defect Leakage to UAT | E22: Defect Leakage to UAT (%)
A23: P0 | B23: 2 | C23: 2 | D23: 0 | E23: 0
A24: P1 | B24: 2 | C24: 2 | D24: 0
A25: P2 | B25: 3 | C25: 3 | D25: 0
